2025-06-11 12:50:23 INFO open for scan: /data2/xxw_data/projects/LLM/Diffusive-Latent-CoT/wandb/offline-run-20250611_122952-m5jc5o8v/run-m5jc5o8v.wandb
2025-06-11 12:51:28 INFO Retry attempt failed:
Traceback (most recent call last):
  File "/data2/xxw_data/data/miniconda3/envs/hybridvla/lib/python3.10/site-packages/urllib3/connection.py", line 198, in _new_conn
    sock = connection.create_connection(
  File "/data2/xxw_data/data/miniconda3/envs/hybridvla/lib/python3.10/site-packages/urllib3/util/connection.py", line 85, in create_connection
    raise err
  File "/data2/xxw_data/data/miniconda3/envs/hybridvla/lib/python3.10/site-packages/urllib3/util/connection.py", line 73, in create_connection
    sock.connect(sa)
TimeoutError: timed out

The above exception was the direct cause of the following exception:

Traceback (most recent call last):
  File "/data2/xxw_data/data/miniconda3/envs/hybridvla/lib/python3.10/site-packages/urllib3/connectionpool.py", line 787, in urlopen
    response = self._make_request(
  File "/data2/xxw_data/data/miniconda3/envs/hybridvla/lib/python3.10/site-packages/urllib3/connectionpool.py", line 488, in _make_request
    raise new_e
  File "/data2/xxw_data/data/miniconda3/envs/hybridvla/lib/python3.10/site-packages/urllib3/connectionpool.py", line 464, in _make_request
    self._validate_conn(conn)
  File "/data2/xxw_data/data/miniconda3/envs/hybridvla/lib/python3.10/site-packages/urllib3/connectionpool.py", line 1093, in _validate_conn
    conn.connect()
  File "/data2/xxw_data/data/miniconda3/envs/hybridvla/lib/python3.10/site-packages/urllib3/connection.py", line 704, in connect
    self.sock = sock = self._new_conn()
  File "/data2/xxw_data/data/miniconda3/envs/hybridvla/lib/python3.10/site-packages/urllib3/connection.py", line 207, in _new_conn
    raise ConnectTimeoutError(
urllib3.exceptions.ConnectTimeoutError: (<urllib3.connection.HTTPSConnection object at 0x7fb39f0d00d0>, 'Connection to api.wandb.ai timed out. (connect timeout=20)')

The above exception was the direct cause of the following exception:

Traceback (most recent call last):
  File "/data2/xxw_data/data/miniconda3/envs/hybridvla/lib/python3.10/site-packages/requests/adapters.py", line 667, in send
    resp = conn.urlopen(
  File "/data2/xxw_data/data/miniconda3/envs/hybridvla/lib/python3.10/site-packages/urllib3/connectionpool.py", line 841, in urlopen
    retries = retries.increment(
  File "/data2/xxw_data/data/miniconda3/envs/hybridvla/lib/python3.10/site-packages/urllib3/util/retry.py", line 519, in increment
    raise MaxRetryError(_pool, url, reason) from reason  # type: ignore[arg-type]
urllib3.exceptions.MaxRetryError: HTTPSConnectionPool(host='api.wandb.ai', port=443): Max retries exceeded with url: /graphql (Caused by ConnectTimeoutError(<urllib3.connection.HTTPSConnection object at 0x7fb39f0d00d0>, 'Connection to api.wandb.ai timed out. (connect timeout=20)'))

During handling of the above exception, another exception occurred:

Traceback (most recent call last):
  File "/data2/xxw_data/data/miniconda3/envs/hybridvla/lib/python3.10/site-packages/wandb/sdk/lib/retry.py", line 131, in __call__
    result = self._call_fn(*args, **kwargs)
  File "/data2/xxw_data/data/miniconda3/envs/hybridvla/lib/python3.10/site-packages/wandb/sdk/internal/internal_api.py", line 393, in execute
    return self.client.execute(*args, **kwargs)  # type: ignore
  File "/data2/xxw_data/data/miniconda3/envs/hybridvla/lib/python3.10/site-packages/wandb/vendor/gql-0.2.0/wandb_gql/client.py", line 52, in execute
    result = self._get_result(document, *args, **kwargs)
  File "/data2/xxw_data/data/miniconda3/envs/hybridvla/lib/python3.10/site-packages/wandb/vendor/gql-0.2.0/wandb_gql/client.py", line 60, in _get_result
    return self.transport.execute(document, *args, **kwargs)
  File "/data2/xxw_data/data/miniconda3/envs/hybridvla/lib/python3.10/site-packages/wandb/sdk/lib/gql_request.py", line 58, in execute
    request = self.session.post(self.url, **post_args)
  File "/data2/xxw_data/data/miniconda3/envs/hybridvla/lib/python3.10/site-packages/requests/sessions.py", line 637, in post
    return self.request("POST", url, data=data, json=json, **kwargs)
  File "/data2/xxw_data/data/miniconda3/envs/hybridvla/lib/python3.10/site-packages/requests/sessions.py", line 589, in request
    resp = self.send(prep, **send_kwargs)
  File "/data2/xxw_data/data/miniconda3/envs/hybridvla/lib/python3.10/site-packages/requests/sessions.py", line 703, in send
    r = adapter.send(request, **kwargs)
  File "/data2/xxw_data/data/miniconda3/envs/hybridvla/lib/python3.10/site-packages/requests/adapters.py", line 688, in send
    raise ConnectTimeout(e, request=request)
requests.exceptions.ConnectTimeout: HTTPSConnectionPool(host='api.wandb.ai', port=443): Max retries exceeded with url: /graphql (Caused by ConnectTimeoutError(<urllib3.connection.HTTPSConnection object at 0x7fb39f0d00d0>, 'Connection to api.wandb.ai timed out. (connect timeout=20)'))
2025-06-11 12:53:59 INFO open for scan: /data2/xxw_data/projects/LLM/Diffusive-Latent-CoT/wandb/offline-run-20250611_122952-m5jc5o8v/run-m5jc5o8v.wandb
2025-06-11 12:54:33 ERROR Retry attempt failed:
Traceback (most recent call last):
  File "/data2/xxw_data/data/miniconda3/envs/hybridvla/lib/python3.10/site-packages/urllib3/connection.py", line 198, in _new_conn
    sock = connection.create_connection(
  File "/data2/xxw_data/data/miniconda3/envs/hybridvla/lib/python3.10/site-packages/urllib3/util/connection.py", line 85, in create_connection
    raise err
  File "/data2/xxw_data/data/miniconda3/envs/hybridvla/lib/python3.10/site-packages/urllib3/util/connection.py", line 73, in create_connection
    sock.connect(sa)
TimeoutError: timed out

The above exception was the direct cause of the following exception:

Traceback (most recent call last):
  File "/data2/xxw_data/data/miniconda3/envs/hybridvla/lib/python3.10/site-packages/urllib3/connectionpool.py", line 787, in urlopen
    response = self._make_request(
  File "/data2/xxw_data/data/miniconda3/envs/hybridvla/lib/python3.10/site-packages/urllib3/connectionpool.py", line 488, in _make_request
    raise new_e
  File "/data2/xxw_data/data/miniconda3/envs/hybridvla/lib/python3.10/site-packages/urllib3/connectionpool.py", line 464, in _make_request
    self._validate_conn(conn)
  File "/data2/xxw_data/data/miniconda3/envs/hybridvla/lib/python3.10/site-packages/urllib3/connectionpool.py", line 1093, in _validate_conn
    conn.connect()
  File "/data2/xxw_data/data/miniconda3/envs/hybridvla/lib/python3.10/site-packages/urllib3/connection.py", line 704, in connect
    self.sock = sock = self._new_conn()
  File "/data2/xxw_data/data/miniconda3/envs/hybridvla/lib/python3.10/site-packages/urllib3/connection.py", line 207, in _new_conn
    raise ConnectTimeoutError(
urllib3.exceptions.ConnectTimeoutError: (<urllib3.connection.HTTPSConnection object at 0x7fccfa565a20>, 'Connection to api.wandb.ai timed out. (connect timeout=10)')

The above exception was the direct cause of the following exception:

Traceback (most recent call last):
  File "/data2/xxw_data/data/miniconda3/envs/hybridvla/lib/python3.10/site-packages/requests/adapters.py", line 667, in send
    resp = conn.urlopen(
  File "/data2/xxw_data/data/miniconda3/envs/hybridvla/lib/python3.10/site-packages/urllib3/connectionpool.py", line 841, in urlopen
    retries = retries.increment(
  File "/data2/xxw_data/data/miniconda3/envs/hybridvla/lib/python3.10/site-packages/urllib3/util/retry.py", line 519, in increment
    raise MaxRetryError(_pool, url, reason) from reason  # type: ignore[arg-type]
urllib3.exceptions.MaxRetryError: HTTPSConnectionPool(host='api.wandb.ai', port=443): Max retries exceeded with url: /graphql (Caused by ConnectTimeoutError(<urllib3.connection.HTTPSConnection object at 0x7fccfa565a20>, 'Connection to api.wandb.ai timed out. (connect timeout=10)'))

During handling of the above exception, another exception occurred:

Traceback (most recent call last):
  File "/data2/xxw_data/data/miniconda3/envs/hybridvla/lib/python3.10/site-packages/wandb/sdk/lib/retry.py", line 102, in __call__
    result = self._call_fn(*args, **kwargs)
  File "/data2/xxw_data/data/miniconda3/envs/hybridvla/lib/python3.10/site-packages/wandb/sdk/internal/internal_api.py", line 140, in execute
    return self.client.execute(*args, **kwargs)
  File "/data2/xxw_data/data/miniconda3/envs/hybridvla/lib/python3.10/site-packages/wandb/vendor/gql-0.2.0/wandb_gql/client.py", line 52, in execute
    result = self._get_result(document, *args, **kwargs)
  File "/data2/xxw_data/data/miniconda3/envs/hybridvla/lib/python3.10/site-packages/wandb/vendor/gql-0.2.0/wandb_gql/client.py", line 60, in _get_result
    return self.transport.execute(document, *args, **kwargs)
  File "/data2/xxw_data/data/miniconda3/envs/hybridvla/lib/python3.10/site-packages/wandb/vendor/gql-0.2.0/wandb_gql/transport/requests.py", line 38, in execute
    request = requests.post(self.url, **post_args)
  File "/data2/xxw_data/data/miniconda3/envs/hybridvla/lib/python3.10/site-packages/requests/api.py", line 115, in post
    return request("post", url, data=data, json=json, **kwargs)
  File "/data2/xxw_data/data/miniconda3/envs/hybridvla/lib/python3.10/site-packages/requests/api.py", line 59, in request
    return session.request(method=method, url=url, **kwargs)
  File "/data2/xxw_data/data/miniconda3/envs/hybridvla/lib/python3.10/site-packages/requests/sessions.py", line 589, in request
    resp = self.send(prep, **send_kwargs)
  File "/data2/xxw_data/data/miniconda3/envs/hybridvla/lib/python3.10/site-packages/requests/sessions.py", line 703, in send
    r = adapter.send(request, **kwargs)
  File "/data2/xxw_data/data/miniconda3/envs/hybridvla/lib/python3.10/site-packages/requests/adapters.py", line 688, in send
    raise ConnectTimeout(e, request=request)
requests.exceptions.ConnectTimeout: HTTPSConnectionPool(host='api.wandb.ai', port=443): Max retries exceeded with url: /graphql (Caused by ConnectTimeoutError(<urllib3.connection.HTTPSConnection object at 0x7fccfa565a20>, 'Connection to api.wandb.ai timed out. (connect timeout=10)'))
2025-06-11 12:58:43 INFO open for scan: /data2/xxw_data/projects/LLM/Diffusive-Latent-CoT/wandb/offline-run-20250611_122952-m5jc5o8v/run-m5jc5o8v.wandb
2025-06-11 12:59:16 ERROR Retry attempt failed:
Traceback (most recent call last):
  File "/data2/xxw_data/data/miniconda3/envs/wandb_env/lib/python3.11/site-packages/urllib3/connection.py", line 198, in _new_conn
    sock = connection.create_connection(
           ^^^^^^^^^^^^^^^^^^^^^^^^^^^^^
  File "/data2/xxw_data/data/miniconda3/envs/wandb_env/lib/python3.11/site-packages/urllib3/util/connection.py", line 85, in create_connection
    raise err
  File "/data2/xxw_data/data/miniconda3/envs/wandb_env/lib/python3.11/site-packages/urllib3/util/connection.py", line 73, in create_connection
    sock.connect(sa)
TimeoutError: timed out

The above exception was the direct cause of the following exception:

Traceback (most recent call last):
  File "/data2/xxw_data/data/miniconda3/envs/wandb_env/lib/python3.11/site-packages/urllib3/connectionpool.py", line 787, in urlopen
    response = self._make_request(
               ^^^^^^^^^^^^^^^^^^^
  File "/data2/xxw_data/data/miniconda3/envs/wandb_env/lib/python3.11/site-packages/urllib3/connectionpool.py", line 488, in _make_request
    raise new_e
  File "/data2/xxw_data/data/miniconda3/envs/wandb_env/lib/python3.11/site-packages/urllib3/connectionpool.py", line 464, in _make_request
    self._validate_conn(conn)
  File "/data2/xxw_data/data/miniconda3/envs/wandb_env/lib/python3.11/site-packages/urllib3/connectionpool.py", line 1093, in _validate_conn
    conn.connect()
  File "/data2/xxw_data/data/miniconda3/envs/wandb_env/lib/python3.11/site-packages/urllib3/connection.py", line 704, in connect
    self.sock = sock = self._new_conn()
                       ^^^^^^^^^^^^^^^^
  File "/data2/xxw_data/data/miniconda3/envs/wandb_env/lib/python3.11/site-packages/urllib3/connection.py", line 207, in _new_conn
    raise ConnectTimeoutError(
urllib3.exceptions.ConnectTimeoutError: (<urllib3.connection.HTTPSConnection object at 0x7f599621b750>, 'Connection to api.wandb.ai timed out. (connect timeout=10)')

The above exception was the direct cause of the following exception:

Traceback (most recent call last):
  File "/data2/xxw_data/data/miniconda3/envs/wandb_env/lib/python3.11/site-packages/requests/adapters.py", line 667, in send
    resp = conn.urlopen(
           ^^^^^^^^^^^^^
  File "/data2/xxw_data/data/miniconda3/envs/wandb_env/lib/python3.11/site-packages/urllib3/connectionpool.py", line 841, in urlopen
    retries = retries.increment(
              ^^^^^^^^^^^^^^^^^^
  File "/data2/xxw_data/data/miniconda3/envs/wandb_env/lib/python3.11/site-packages/urllib3/util/retry.py", line 519, in increment
    raise MaxRetryError(_pool, url, reason) from reason  # type: ignore[arg-type]
    ^^^^^^^^^^^^^^^^^^^^^^^^^^^^^^^^^^^^^^^^^^^^^^^^^^^
urllib3.exceptions.MaxRetryError: HTTPSConnectionPool(host='api.wandb.ai', port=443): Max retries exceeded with url: /graphql (Caused by ConnectTimeoutError(<urllib3.connection.HTTPSConnection object at 0x7f599621b750>, 'Connection to api.wandb.ai timed out. (connect timeout=10)'))

During handling of the above exception, another exception occurred:

Traceback (most recent call last):
  File "/data2/xxw_data/data/miniconda3/envs/wandb_env/lib/python3.11/site-packages/wandb/sdk/lib/retry.py", line 102, in __call__
    result = self._call_fn(*args, **kwargs)
             ^^^^^^^^^^^^^^^^^^^^^^^^^^^^^^
  File "/data2/xxw_data/data/miniconda3/envs/wandb_env/lib/python3.11/site-packages/wandb/sdk/internal/internal_api.py", line 140, in execute
    return self.client.execute(*args, **kwargs)
           ^^^^^^^^^^^^^^^^^^^^^^^^^^^^^^^^^^^^
  File "/data2/xxw_data/data/miniconda3/envs/wandb_env/lib/python3.11/site-packages/wandb/vendor/gql-0.2.0/wandb_gql/client.py", line 52, in execute
    result = self._get_result(document, *args, **kwargs)
             ^^^^^^^^^^^^^^^^^^^^^^^^^^^^^^^^^^^^^^^^^^^
  File "/data2/xxw_data/data/miniconda3/envs/wandb_env/lib/python3.11/site-packages/wandb/vendor/gql-0.2.0/wandb_gql/client.py", line 60, in _get_result
    return self.transport.execute(document, *args, **kwargs)
           ^^^^^^^^^^^^^^^^^^^^^^^^^^^^^^^^^^^^^^^^^^^^^^^^^
  File "/data2/xxw_data/data/miniconda3/envs/wandb_env/lib/python3.11/site-packages/wandb/vendor/gql-0.2.0/wandb_gql/transport/requests.py", line 38, in execute
    request = requests.post(self.url, **post_args)
              ^^^^^^^^^^^^^^^^^^^^^^^^^^^^^^^^^^^^
  File "/data2/xxw_data/data/miniconda3/envs/wandb_env/lib/python3.11/site-packages/requests/api.py", line 115, in post
    return request("post", url, data=data, json=json, **kwargs)
           ^^^^^^^^^^^^^^^^^^^^^^^^^^^^^^^^^^^^^^^^^^^^^^^^^^^^
  File "/data2/xxw_data/data/miniconda3/envs/wandb_env/lib/python3.11/site-packages/requests/api.py", line 59, in request
    return session.request(method=method, url=url, **kwargs)
           ^^^^^^^^^^^^^^^^^^^^^^^^^^^^^^^^^^^^^^^^^^^^^^^^^
  File "/data2/xxw_data/data/miniconda3/envs/wandb_env/lib/python3.11/site-packages/requests/sessions.py", line 589, in request
    resp = self.send(prep, **send_kwargs)
           ^^^^^^^^^^^^^^^^^^^^^^^^^^^^^^
  File "/data2/xxw_data/data/miniconda3/envs/wandb_env/lib/python3.11/site-packages/requests/sessions.py", line 703, in send
    r = adapter.send(request, **kwargs)
        ^^^^^^^^^^^^^^^^^^^^^^^^^^^^^^^
  File "/data2/xxw_data/data/miniconda3/envs/wandb_env/lib/python3.11/site-packages/requests/adapters.py", line 688, in send
    raise ConnectTimeout(e, request=request)
requests.exceptions.ConnectTimeout: HTTPSConnectionPool(host='api.wandb.ai', port=443): Max retries exceeded with url: /graphql (Caused by ConnectTimeoutError(<urllib3.connection.HTTPSConnection object at 0x7f599621b750>, 'Connection to api.wandb.ai timed out. (connect timeout=10)'))
2025-06-11 13:03:45 INFO open for scan: /data2/xxw_data/projects/LLM/Diffusive-Latent-CoT/wandb/offline-run-20250611_122952-m5jc5o8v/run-m5jc5o8v.wandb
2025-06-11 13:04:18 ERROR Retry attempt failed:
Traceback (most recent call last):
  File "/data2/xxw_data/data/miniconda3/envs/hybridvla/lib/python3.10/site-packages/urllib3/connection.py", line 198, in _new_conn
    sock = connection.create_connection(
  File "/data2/xxw_data/data/miniconda3/envs/hybridvla/lib/python3.10/site-packages/urllib3/util/connection.py", line 85, in create_connection
    raise err
  File "/data2/xxw_data/data/miniconda3/envs/hybridvla/lib/python3.10/site-packages/urllib3/util/connection.py", line 73, in create_connection
    sock.connect(sa)
TimeoutError: timed out

The above exception was the direct cause of the following exception:

Traceback (most recent call last):
  File "/data2/xxw_data/data/miniconda3/envs/hybridvla/lib/python3.10/site-packages/urllib3/connectionpool.py", line 787, in urlopen
    response = self._make_request(
  File "/data2/xxw_data/data/miniconda3/envs/hybridvla/lib/python3.10/site-packages/urllib3/connectionpool.py", line 488, in _make_request
    raise new_e
  File "/data2/xxw_data/data/miniconda3/envs/hybridvla/lib/python3.10/site-packages/urllib3/connectionpool.py", line 464, in _make_request
    self._validate_conn(conn)
  File "/data2/xxw_data/data/miniconda3/envs/hybridvla/lib/python3.10/site-packages/urllib3/connectionpool.py", line 1093, in _validate_conn
    conn.connect()
  File "/data2/xxw_data/data/miniconda3/envs/hybridvla/lib/python3.10/site-packages/urllib3/connection.py", line 704, in connect
    self.sock = sock = self._new_conn()
  File "/data2/xxw_data/data/miniconda3/envs/hybridvla/lib/python3.10/site-packages/urllib3/connection.py", line 207, in _new_conn
    raise ConnectTimeoutError(
urllib3.exceptions.ConnectTimeoutError: (<urllib3.connection.HTTPSConnection object at 0x7fe4af985a20>, 'Connection to api.wandb.ai timed out. (connect timeout=10)')

The above exception was the direct cause of the following exception:

Traceback (most recent call last):
  File "/data2/xxw_data/data/miniconda3/envs/hybridvla/lib/python3.10/site-packages/requests/adapters.py", line 667, in send
    resp = conn.urlopen(
  File "/data2/xxw_data/data/miniconda3/envs/hybridvla/lib/python3.10/site-packages/urllib3/connectionpool.py", line 841, in urlopen
    retries = retries.increment(
  File "/data2/xxw_data/data/miniconda3/envs/hybridvla/lib/python3.10/site-packages/urllib3/util/retry.py", line 519, in increment
    raise MaxRetryError(_pool, url, reason) from reason  # type: ignore[arg-type]
urllib3.exceptions.MaxRetryError: HTTPSConnectionPool(host='api.wandb.ai', port=443): Max retries exceeded with url: /graphql (Caused by ConnectTimeoutError(<urllib3.connection.HTTPSConnection object at 0x7fe4af985a20>, 'Connection to api.wandb.ai timed out. (connect timeout=10)'))

During handling of the above exception, another exception occurred:

Traceback (most recent call last):
  File "/data2/xxw_data/data/miniconda3/envs/hybridvla/lib/python3.10/site-packages/wandb/sdk/lib/retry.py", line 102, in __call__
    result = self._call_fn(*args, **kwargs)
  File "/data2/xxw_data/data/miniconda3/envs/hybridvla/lib/python3.10/site-packages/wandb/sdk/internal/internal_api.py", line 140, in execute
    return self.client.execute(*args, **kwargs)
  File "/data2/xxw_data/data/miniconda3/envs/hybridvla/lib/python3.10/site-packages/wandb/vendor/gql-0.2.0/wandb_gql/client.py", line 52, in execute
    result = self._get_result(document, *args, **kwargs)
  File "/data2/xxw_data/data/miniconda3/envs/hybridvla/lib/python3.10/site-packages/wandb/vendor/gql-0.2.0/wandb_gql/client.py", line 60, in _get_result
    return self.transport.execute(document, *args, **kwargs)
  File "/data2/xxw_data/data/miniconda3/envs/hybridvla/lib/python3.10/site-packages/wandb/vendor/gql-0.2.0/wandb_gql/transport/requests.py", line 38, in execute
    request = requests.post(self.url, **post_args)
  File "/data2/xxw_data/data/miniconda3/envs/hybridvla/lib/python3.10/site-packages/requests/api.py", line 115, in post
    return request("post", url, data=data, json=json, **kwargs)
  File "/data2/xxw_data/data/miniconda3/envs/hybridvla/lib/python3.10/site-packages/requests/api.py", line 59, in request
    return session.request(method=method, url=url, **kwargs)
  File "/data2/xxw_data/data/miniconda3/envs/hybridvla/lib/python3.10/site-packages/requests/sessions.py", line 589, in request
    resp = self.send(prep, **send_kwargs)
  File "/data2/xxw_data/data/miniconda3/envs/hybridvla/lib/python3.10/site-packages/requests/sessions.py", line 703, in send
    r = adapter.send(request, **kwargs)
  File "/data2/xxw_data/data/miniconda3/envs/hybridvla/lib/python3.10/site-packages/requests/adapters.py", line 688, in send
    raise ConnectTimeout(e, request=request)
requests.exceptions.ConnectTimeout: HTTPSConnectionPool(host='api.wandb.ai', port=443): Max retries exceeded with url: /graphql (Caused by ConnectTimeoutError(<urllib3.connection.HTTPSConnection object at 0x7fe4af985a20>, 'Connection to api.wandb.ai timed out. (connect timeout=10)'))
